Workbook

Sheet Portada
B4: OBSERVATORIO DE DEFORESTACIÓN
B5: Jurisdicción CORPOURABA · 19 municipios · 2000-2024
B8: Fecha de generación: 05/07/2026
B9: Elaborado por: Alberto Vivas y Carlos Zuluaga
B10: Datos: paquete institucional de monitoreo de bosque CORPOURABA (IDEAM/SMByC)
B13: Contenido del libro
B14: Dashboard | C14: KPIs, serie regional anualizada, top-10 municipios y distribución por territorial
B15: Territoriales | C15: Deforestación por cada una de las 5 territoriales de CORPOURABA (tabla + gráfico)
B16: Consulta municipio | C16: Ficha dinámica por municipio (lista desplegable en la celda amarilla)
B17: Matriz | C17: Municipio × periodo con escala de color y totales
B18: Serie regional | C18: Serie agregada por periodo (fórmulas sobre los datos)
B19: Serie municipal | C19: Datos fuente completos (1131 filas) con autofiltro
B20: Aux | C20: Cálculos auxiliares (totales por municipio, ranking, territoriales)
B21: Dinámica bosque | C21: Resultados de la investigación temática
B22: Hallazgos | C22: Resultados de la investigación temática
B23: Territorios | C23: Resultados de la investigación temática
B24: Diccionario | C24: Definiciones, vacíos, calibraciones y control de calidad
B27: Todos los indicadores del libro son fórmulas de Excel (SUMIFS/INDEX/MATCH/LARGE) sobre la hoja «Serie municipal»: puede auditarse y extenderse sin herramientas adicionales. Los periodos con fondo crema son estimados/calibrados.

Sheet Serie municipal
A1: Código DANE | B1: Municipio | C1: Territorial | D1: Periodo | E1: Año inicio | F1: Año fin | G1: Clase | H1: Hectáreas | I1: Ha/año | J1: Fuente | K1: Estimado
A2: 05004 | B2: Abriaquí | C2: Nutibara | D2: 2000-2002 | E2: 2000 | F2: 2002 | G2: Bosque Estable | H2: 13423.94 | I2: 6711.97 | J2: excel | K2: No
A3: 05004 | B3: Abriaquí | C3: Nutibara | D3: 2000-2002 | E3: 2000 | F3: 2002 | G3: Deforestación | H3: 9.05 | I3: 4.53 | J3: excel | K3: No
A4: 05004 | B4: Abriaquí | C4: Nutibara | D4: 2000-2002 | E4: 2000 | F4: 2002 | G4: No Bosque Estable | H4: 16259.23 | I4: 8129.62 | J4: excel | K4: No
A5: 05045 | B5: Apartadó | C5: Centro | D5: 2000-2002 | E5: 2000 | F5: 2002 | G5: Bosque Estable | H5: 17703.41 | I5: 8851.7 | J5: excel | K5: No
A6: 05045 | B6: Apartadó | C6: Centro | D6: 2000-2002 | E6: 2000 | F6: 2002 | G6: Deforestación | H6: 16.41 | I6: 8.2 | J6: excel | K6: No
A7: 05045 | B7: Apartadó | C7: Centro | D7: 2000-2002 | E7: 2000 | F7: 2002 | G7: No Bosque Estable | H7: 35423.51 | I7: 17711.76 | J7: excel | K7: No
A8: 05045 | B8: Apartadó | C8: Centro | D8: 2000-2002 | E8: 2000 | F8: 2002 | G8: Sin Información | H8: 252.81 | I8: 126.4 | J8: excel | K8: No
A9: 05051 | B9: Arboletes | C9: Caribe | D9: 2000-2002 | E9: 2000 | F9: 2002 | G9: Bosque Estable | H9: 1237.91 | I9: 618.96 | J9: excel | K9: No
A10: 05051 | B10: Arboletes | C10: Caribe | D10: 2000-2002 | E10: 2000 | F10: 2002 | G10: Deforestación | H10: 2.68 | I10: 1.34 | J10: excel | K10: No
A11: 05051 | B11: Arboletes | C11: Caribe | D11: 2000-2002 | E11: 2000 | F11: 2002 | G11: No Bosque Estable | H11: 72954.65 | I11: 36477.32 | J11: excel | K11: No
A12: 05051 | B12: Arboletes | C12: Caribe | D12: 2000-2002 | E12: 2000 | F12: 2002 | G12: Sin Información | H12: 0.75 | I12: 0.38 | J12: excel | K12: No
A13: 05147 | B13: Carepa | C13: Centro | D13: 2000-2002 | E13: 2000 | F13: 2002 | G13: Bosque Estable | H13: 6956.56 | I13: 3478.28 | J13: excel | K13: No
... A1132: 05873 | B1132: Vigía del Fuerte | C1132: Atrato | D1132: 2023-2024 | E1132: 2023 | F1132: 2024 | G1132: Deforestación | H1132: 12.99 | I1132: 12.99 | J1132: estimado | K1132: Sí

Sheet Dashboard
B2: DASHBOARD — DEFORESTACIÓN CORPOURABA 2000-2024
B3: 19 municipios · 18 periodos de monitoreo · fórmulas auditables sobre la hoja «Serie municipal»
B5: ='Serie regional'!E20 -> 46845.52 | E5: ='Serie regional'!E20/24 -> 1951.8967 | H5: =INDEX('Serie regional'!A2:A19,MATCH(MAX('Serie regional'!E2:E19),'Serie regional'!E2:E19,0)) -> 2015-2016 | K5: =Aux!G4 -> Turbo
B7: Total deforestado (ha) | E7: Promedio anual (ha/año) | H7: Periodo más crítico | K7: Municipio más afectado
B8: Nota: los periodos marcados con * son estimados/calibrados (2010-2012, 2018-2019, 2023-2024). 2015-2016 es dato real recuperado de la tabla municipal oficial.

Sheet Consulta municipio
B2: CONSULTA POR MUNICIPIO
B4: Seleccione municipio: | E4: Abriaquí | G4: (desplegable — celda amarilla)
B7: =SUM(B11:B28) -> 311.54 | E7: =B7/'Serie regional'!$E$20 -> 0.0066503691 | H7: =INDEX(A11:A28,MATCH(MAX(B11:B28),B11:B28,0)) -> 2012-2013 | K7: =INDEX(Aux!$B$4:$B$22,MATCH($E$4,Aux!$A$4:$A$22,0)) -> Nutibara
B8: Total 2000-2024 (ha) | E8: % del total regional | H8: Periodo más crítico | K8: Territorial
A10: Periodo | B10: Deforestación (ha) | C10: Ha/año | D10: Ha/año regional | E10: Estimado
A11: ='Serie regional'!A2 -> 2000-2002 | B11: =SUMIFS('Serie municipal'!$H$2:$H$1132,'Serie municipal'!$B$2:$B$1132,$E$4,'Serie municipal'!$G$2:$G$1132,"Deforestación",'Serie municipal'!$D$2:$D$1132,$A$11) -> 9.05 | C11: =B11/'Serie regional'!D2 -> 4.525 | D11: ='Serie regional'!F2 -> 795.15 | E11: ='Serie regional'!G2 -> No
A12: ='Serie regional'!A3 -> 2002-2004 | B12: =SUMIFS('Serie municipal'!$H$2:$H$1132,'Serie municipal'!$B$2:$B$1132,$E$4,'Serie municipal'!$G$2:$G$1132,"Deforestación",'Serie municipal'!$D$2:$D$1132,$A$12) -> 8.99 | C12: =B12/'Serie regional'!D3 -> 4.495 | D12: ='Serie regional'!F3 -> 1858.955 | E12: ='Serie regional'!G3 -> No
A13: ='Serie regional'!A4 -> 2004-2006 | B13: =SUMIFS('Serie municipal'!$H$2:$H$1132,'Serie municipal'!$B$2:$B$1132,$E$4,'Serie municipal'!$G$2:$G$1132,"Deforestación",'Serie municipal'!$D$2:$D$1132,$A$13) -> 0 | C13: =B13/'Serie regional'!D4 -> 0 | D13: ='Serie regional'!F4 -> 1510.825 | E13: ='Serie regional'!G4 -> No
A14: ='Serie regional'!A5 -> 2006-2008 | B14: =SUMIFS('Serie municipal'!$H$2:$H$1132,'Serie municipal'!$B$2:$B$1132,$E$4,'Serie municipal'!$G$2:$G$1132,"Deforestación",'Serie municipal'!$D$2:$D$1132,$A$14) -> 1.47 | C14: =B14/'Serie regional'!D5 -> 0.735 | D14: ='Serie regional'!F5 -> 1269.755 | E14: ='Serie regional'!G5 -> No
A15: ='Serie regional'!A6 -> 2008-2010 | B15: =SUMIFS('Serie municipal'!$H$2:$H$1132,'Serie municipal'!$B$2:$B$1132,$E$4,'Serie municipal'!$G$2:$G$1132,"Deforestación",'Serie municipal'!$D$2:$D$1132,$A$15) -> 2.95 | C15: =B15/'Serie regional'!D6 -> 1.475 | D15: ='Serie regional'!F6 -> 1460.68 | E15: ='Serie regional'!G6 -> No
A16: ='Serie regional'!A7 -> 2010-2012 | B16: =SUMIFS('Serie municipal'!$H$2:$H$1132,'Serie municipal'!$B$2:$B$1132,$E$4,'Serie municipal'!$G$2:$G$1132,"Deforestación",'Serie municipal'!$D$2:$D$1132,$A$16) -> 74.44 | C16: =B16/'Serie regional'!D7 -> 37.22 | D16: ='Serie regional'!F7 -> 1567.45 | E16: ='Serie regional'!G7 -> Sí
A17: ='Serie regional'!A8 -> 2012-2013 | B17: =SUMIFS('Serie municipal'!$H$2:$H$1132,'Serie municipal'!$B$2:$B$1132,$E$4,'Serie municipal'!$G$2:$G$1132,"Deforestación",'Serie municipal'!$D$2:$D$1132,$A$17) -> 87.29 | C17: =B17/'Serie regional'!D8 -> 87.29 | D17: ='Serie regional'!F8 -> 2273.94 | E17: ='Serie regional'!G8 -> No
A18: ='Serie regional'!A9 -> 2013-2014 | B18: =SUMIFS('Serie municipal'!$H$2:$H$1132,'Serie municipal'!$B$2:$B$1132,$E$4,'Serie municipal'!$G$2:$G$1132,"Deforestación",'Serie municipal'!$D$2:$D$1132,$A$18) -> 15.25 | C18: =B18/'Serie regional'!D9 -> 15.25 | D18: ='Serie regional'!F9 -> 3576.99 | E18: ='Serie regional'!G9 -> No
A19: ='Serie regional'!A10 -> 2014-2015 | B19: =SUMIFS('Serie municipal'!$H$2:$H$1132,'Serie municipal'!$B$2:$B$1132,$E$4,'Serie municipal'!$G$2:$G$1132,"Deforestación",'Serie municipal'!$D$2:$D$1132,$A$19) -> 17.09 | C19: =B19/'Serie regional'!D10 -> 17.09 | D19: ='Serie regional'!F10 -> 2887.49 | E19: ='Serie regional'!G10 -> No
A20: ='Serie regional'!A11 -> 2015-2016 | B20: =SUMIFS('Serie municipal'!$H$2:$H$1132,'Serie municipal'!$B$2:$B$1132,$E$4,'Serie municipal'!$G$2:$G$1132,"Deforestación",'Serie municipal'!$D$2:$D$1132,$A$20) -> 25.12 | C20: =B20/'Serie regional'!D11 -> 25.12 | D20: ='Serie regional'!F11 -> 5771.04 | E20: ='Serie regional'!G11 -> No
A21: ='Serie regional'!A12 -> 2016-2017 | B21: =SUMIFS('Serie municipal'!$H$2:$H$1132,'Serie municipal'!$B$2:$B$1132,$E$4,'Serie municipal'!$G$2:$G$1132,"Deforestación",'Serie municipal'!$D$2:$D$1132,$A$21) -> 35.66 | C21: =B21/'Serie regional'!D12 -> 35.66 | D21: ='Serie regional'!F12 -> 3938.39 | E21: ='Serie regional'!G12 -> No
A22: ='Serie regional'!A13 -> 2017-2018 | B22: =SUMIFS('Serie municipal'!$H$2:$H$1132,'Serie municipal'!$B$2:$B$1132,$E$4,'Serie municipal'!$G$2:$G$1132,"Deforestación",'Serie municipal'!$D$2:$D$1132,$A$22) -> 4.28 | C22: =B22/'Serie regional'!D13 -> 4.28 | D22: ='Serie regional'!F13 -> 1765.16 | E22: ='Serie regional'!G13 -> No
A23: ='Serie regional'!A14 -> 2018-2019 | B23: =SUMIFS('Serie municipal'!$H$2:$H$1132,'Serie municipal'!$B$2:$B$1132,$E$4,'Serie municipal'!$G$2:$G$1132,"Deforestación",'Serie municipal'!$D$2:$D$1132,$A$23) -> 2.7 | C23: =B23/'Serie regional'!D14 -> 2.7 | D23: ='Serie regional'!F14 -> 1800.17 | E23: ='Serie regional'!G14 -> Sí
A24: ='Serie regional'!A15 -> 2019-2020 | B24: =SUMIFS('Serie municipal'!$H$2:$H$1132,'Serie municipal'!$B$2:$B$1132,$E$4,'Serie municipal'!$G$2:$G$1132,"Deforestación",'Serie municipal'!$D$2:$D$1132,$A$24) -> 1.12 | C24: =B24/'Serie regional'!D15 -> 1.12 | D24: ='Serie regional'!F15 -> 1737.29 | E24: ='Serie regional'!G15 -> No
A25: ='Serie regional'!A16 -> 2020-2021 | B25: =SUMIFS('Serie municipal'!$H$2:$H$1132,'Serie municipal'!$B$2:$B$1132,$E$4,'Serie municipal'!$G$2:$G$1132,"Deforestación",'Serie municipal'!$D$2:$D$1132,$A$25) -> 0 | C25: =B25/'Serie regional'!D16 -> 0 | D25: ='Serie regional'!F16 -> 1090.76 | E25: ='Serie regional'!G16 -> No
A26: ='Serie regional'!A17 -> 2021-2022 | B26: =SUMIFS('Serie municipal'!$H$2:$H$1132,'Serie municipal'!$B$2:$B$1132,$E$4,'Serie municipal'!$G$2:$G$1132,"Deforestación",'Serie municipal'!$D$2:$D$1132,$A$26) -> 5.77 | C26: =B26/'Serie regional'!D17 -> 5.77 | D26: ='Serie regional'!F17 -> 2325.63 | E26: ='Serie regional'!G17 -> No
A27: ='Serie regional'!A18 -> 2022-2023 | B27: =SUMIFS('Serie municipal'!$H$2:$H$1132,'Serie municipal'!$B$2:$B$1132,$E$4,'Serie municipal'!$G$2:$G$1132,"Deforestación",'Serie municipal'!$D$2:$D$1132,$A$27) -> 8.22 | C27: =B27/'Serie regional'!D18 -> 8.22 | D27: ='Serie regional'!F18 -> 1156.22 | E27: ='Serie regional'!G18 -> No
A28: ='Serie regional'!A19 -> 2023-2024 | B28: =SUMIFS('Serie municipal'!$H$2:$H$1132,'Serie municipal'!$B$2:$B$1132,$E$4,'Serie municipal'!$G$2:$G$1132,"Deforestación",'Serie municipal'!$D$2:$D$1132,$A$28) -> 12.14 | C28: =B28/'Serie regional'!D19 -> 12.14 | D28: ='Serie regional'!F19 -> 1596.81 | E28: ='Serie regional'!G19 -> Sí

Sheet Matriz
A1: Matriz de deforestación (ha) — municipio × periodo
A3: Municipio | B3: 2000-2002 | C3: 2002-2004 | D3: 2004-2006 | E3: 2006-2008 | F3: 2008-2010 | G3: 2010-2012 | H3: 2012-2013 | I3: 2013-2014 | J3: 2014-2015 | K3: 2015-2016 | L3: 2016-2017 | M3: 2017-2018 | N3: 2018-2019 | O3: 2019-2020 | P3: 2020-2021 | Q3: 2021-2022 | R3: 2022-2023 | S3: 2023-2024 | T3: TOTAL
A4: Abriaquí | B4: =SUMIFS('Serie municipal'!$H$2:$H$1132,'Serie municipal'!$B$2:$B$1132,$A4,'Serie municipal'!$G$2:$G$1132,"Deforestación",'Serie municipal'!$D$2:$D$1132,B$3) -> 9.05 | C4: =SUMIFS('Serie municipal'!$H$2:$H$1132,'Serie municipal'!$B$2:$B$1132,$A4,'Serie municipal'!$G$2:$G$1132,"Deforestación",'Serie municipal'!$D$2:$D$1132,C$3) -> 8.99 | D4: =SUMIFS('Serie municipal'!$H$2:$H$1132,'Serie municipal'!$B$2:$B$1132,$A4,'Serie municipal'!$G$2:$G$1132,"Deforestación",'Serie municipal'!$D$2:$D$1132,D$3) -> 0 | E4: =SUMIFS('Serie municipal'!$H$2:$H$1132,'Serie municipal'!$B$2:$B$1132,$A4,'Serie municipal'!$G$2:$G$1132,"Deforestación",'Serie municipal'!$D$2:$D$1132,E$3) -> 1.47 | F4: =SUMIFS('Serie municipal'!$H$2:$H$1132,'Serie municipal'!$B$2:$B$1132,$A4,'Serie municipal'!$G$2:$G$1132,"Deforestación",'Serie municipal'!$D$2:$D$1132,F$3) -> 2.95 | G4: =SUMIFS('Serie municipal'!$H$2:$H$1132,'Serie municipal'!$B$2:$B$1132,$A4,'Serie municipal'!$G$2:$G$1132,"Deforestación",'Serie municipal'!$D$2:$D$1132,G$3) -> 74.44 | H4: =SUMIFS('Serie municipal'!$H$2:$H$1132,'Serie municipal'!$B$2:$B$1132,$A4,'Serie municipal'!$G$2:$G$1132,"Deforestación",'Serie municipal'!$D$2:$D$1132,H$3) -> 87.29 | I4: =SUMIFS('Serie municipal'!$H$2:$H$1132,'Serie municipal'!$B$2:$B$1132,$A4,'Serie municipal'!$G$2:$G$1132,"Deforestación",'Serie municipal'!$D$2:$D$1132,I$3) -> 15.25 | ... S4: =SUMIFS('Serie municipal'!$H$2:$H$1132,'Serie municipal'!$B$2:$B$1132,$A4,'Serie municipal'!$G$2:$G$1132,"Deforestación",'Serie municipal'!$D$2:$D$1132,S$3) -> 12.14 | T4: =SUM(B4:S4) -> 311.54
A5: Apartadó | B5: =SUMIFS('Serie municipal'!$H$2:$H$1132,'Serie municipal'!$B$2:$B$1132,$A5,'Serie municipal'!$G$2:$G$1132,"Deforestación",'Serie municipal'!$D$2:$D$1132,B$3) -> 16.41 | C5: =SUMIFS('Serie municipal'!$H$2:$H$1132,'Serie municipal'!$B$2:$B$1132,$A5,'Serie municipal'!$G$2:$G$1132,"Deforestación",'Serie municipal'!$D$2:$D$1132,C$3) -> 40.27 | D5: =SUMIFS('Serie municipal'!$H$2:$H$1132,'Serie municipal'!$B$2:$B$1132,$A5,'Serie municipal'!$G$2:$G$1132,"Deforestación",'Serie municipal'!$D$2:$D$1132,D$3) -> 62.23 | E5: =SUMIFS('Serie municipal'!$H$2:$H$1132,'Serie municipal'!$B$2:$B$1132,$A5,'Serie municipal'!$G$2:$G$1132,"Deforestación",'Serie municipal'!$D$2:$D$1132,E$3) -> 199.72 | F5: =SUMIFS('Serie municipal'!$H$2:$H$1132,'Serie municipal'!$B$2:$B$1132,$A5,'Serie municipal'!$G$2:$G$1132,"Deforestación",'Serie municipal'!$D$2:$D$1132,F$3) -> 102.76 | G5: =SUMIFS('Serie municipal'!$H$2:$H$1132,'Serie municipal'!$B$2:$B$1132,$A5,'Serie municipal'!$G$2:$G$1132,"Deforestación",'Serie municipal'!$D$2:$D$1132,G$3) -> 88.39 | H5: =SUMIFS('Serie municipal'!$H$2:$H$1132,'Serie municipal'!$B$2:$B$1132,$A5,'Serie municipal'!$G$2:$G$1132,"Deforestación",'Serie municipal'!$D$2:$D$1132,H$3) -> 54.01 | I5: =SUMIFS('Serie municipal'!$H$2:$H$1132,'Serie municipal'!$B$2:$B$1132,$A5,'Serie municipal'!$G$2:$G$1132,"Deforestación",'Serie municipal'!$D$2:$D$1132,I$3) -> 410.94 | ... S5: =SUMIFS('Serie municipal'!$H$2:$H$1132,'Serie municipal'!$B$2:$B$1132,$A5,'Serie municipal'!$G$2:$G$1132,"Deforestación",'Serie municipal'!$D$2:$D$1132,S$3) -> 78.45 | T5: =SUM(B5:S5) -> 2271.64
A6: Arboletes | B6: =SUMIFS('Serie municipal'!$H$2:$H$1132,'Serie municipal'!$B$2:$B$1132,$A6,'Serie municipal'!$G$2:$G$1132,"Deforestación",'Serie municipal'!$D$2:$D$1132,B$3) -> 2.68 | C6: =SUMIFS('Serie municipal'!$H$2:$H$1132,'Serie municipal'!$B$2:$B$1132,$A6,'Serie municipal'!$G$2:$G$1132,"Deforestación",'Serie municipal'!$D$2:$D$1132,C$3) -> 6.56 | D6: =SUMIFS('Serie municipal'!$H$2:$H$1132,'Serie municipal'!$B$2:$B$1132,$A6,'Serie municipal'!$G$2:$G$1132,"Deforestación",'Serie municipal'!$D$2:$D$1132,D$3) -> 156.71 | E6: =SUMIFS('Serie municipal'!$H$2:$H$1132,'Serie municipal'!$B$2:$B$1132,$A6,'Serie municipal'!$G$2:$G$1132,"Deforestación",'Serie municipal'!$D$2:$D$1132,E$3) -> 82.77 | F6: =SUMIFS('Serie municipal'!$H$2:$H$1132,'Serie municipal'!$B$2:$B$1132,$A6,'Serie municipal'!$G$2:$G$1132,"Deforestación",'Serie municipal'!$D$2:$D$1132,F$3) -> 23.54 | G6: =SUMIFS('Serie municipal'!$H$2:$H$1132,'Serie municipal'!$B$2:$B$1132,$A6,'Serie municipal'!$G$2:$G$1132,"Deforestación",'Serie municipal'!$D$2:$D$1132,G$3) -> 31.85 | H6: =SUMIFS('Serie municipal'!$H$2:$H$1132,'Serie municipal'!$B$2:$B$1132,$A6,'Serie municipal'!$G$2:$G$1132,"Deforestación",'Serie municipal'!$D$2:$D$1132,H$3) -> 26.21 | I6: =SUMIFS('Serie municipal'!$H$2:$H$1132,'Serie municipal'!$B$2:$B$1132,$A6,'Serie municipal'!$G$2:$G$1132,"Deforestación",'Serie municipal'!$D$2:$D$1132,I$3) -> 1.53 | ... S6: =SUMIFS('Serie municipal'!$H$2:$H$1132,'Serie municipal'!$B$2:$B$1132,$A6,'Serie municipal'!$G$2:$G$1132,"Deforestación",'Serie municipal'!$D$2:$D$1132,S$3) -> 55.82 | T6: =SUM(B6:S6) -> 537.14
A7: Carepa | B7: =SUMIFS('Serie municipal'!$H$2:$H$1132,'Serie municipal'!$B$2:$B$1132,$A7,'Serie municipal'!$G$2:$G$1132,"Deforestación",'Serie municipal'!$D$2:$D$1132,B$3) -> 19.71 | C7: =SUMIFS('Serie municipal'!$H$2:$H$1132,'Serie municipal'!$B$2:$B$1132,$A7,'Serie municipal'!$G$2:$G$1132,"Deforestación",'Serie municipal'!$D$2:$D$1132,C$3) -> 269.2 | D7: =SUMIFS('Serie municipal'!$H$2:$H$1132,'Serie municipal'!$B$2:$B$1132,$A7,'Serie municipal'!$G$2:$G$1132,"Deforestación",'Serie municipal'!$D$2:$D$1132,D$3) -> 69.28 | E7: =SUMIFS('Serie municipal'!$H$2:$H$1132,'Serie municipal'!$B$2:$B$1132,$A7,'Serie municipal'!$G$2:$G$1132,"Deforestación",'Serie municipal'!$D$2:$D$1132,E$3) -> 122.76 | F7: =SUMIFS('Serie municipal'!$H$2:$H$1132,'Serie municipal'!$B$2:$B$1132,$A7,'Serie municipal'!$G$2:$G$1132,"Deforestación",'Serie municipal'!$D$2:$D$1132,F$3) -> 351.2 | G7: =SUMIFS('Serie municipal'!$H$2:$H$1132,'Serie municipal'!$B$2:$B$1132,$A7,'Serie municipal'!$G$2:$G$1132,"Deforestación",'Serie municipal'!$D$2:$D$1132,G$3) -> 158.57 | H7: =SUMIFS('Serie municipal'!$H$2:$H$1132,'Serie municipal'!$B$2:$B$1132,$A7,'Serie municipal'!$G$2:$G$1132,"Deforestación",'Serie municipal'!$D$2:$D$1132,H$3) -> 13.48 | I7: =SUMIFS('Serie municipal'!$H$2:$H$1132,'Serie municipal'!$B$2:$B$1132,$A7,'Serie municipal'!$G$2:$G$1132,"Deforestación",'Serie municipal'!$D$2:$D$1132,I$3) -> 18.78 | ... S7: =SUMIFS('Serie municipal'!$H$2:$H$1132,'Serie municipal'!$B$2:$B$1132,$A7,'Serie municipal'!$G$2:$G$1132,"Deforestación",'Serie municipal'!$D$2:$D$1132,S$3) -> 0 | T7: =SUM(B7:S7) -> 2026.08
A8: Cañasgordas | B8: =SUMIFS('Serie municipal'!$H$2:$H$1132,'Serie municipal'!$B$2:$B$1132,$A8,'Serie municipal'!$G$2:$G$1132,"Deforestación",'Serie municipal'!$D$2:$D$1132,B$3) -> 8.04 | C8: =SUMIFS('Serie municipal'!$H$2:$H$1132,'Serie municipal'!$B$2:$B$1132,$A8,'Serie municipal'!$G$2:$G$1132,"Deforestación",'Serie municipal'!$D$2:$D$1132,C$3) -> 12.38 | D8: =SUMIFS('Serie municipal'!$H$2:$H$1132,'Serie municipal'!$B$2:$B$1132,$A8,'Serie municipal'!$G$2:$G$1132,"Deforestación",'Serie municipal'!$D$2:$D$1132,D$3) -> 22.27 | E8: =SUMIFS('Serie municipal'!$H$2:$H$1132,'Serie municipal'!$B$2:$B$1132,$A8,'Serie municipal'!$G$2:$G$1132,"Deforestación",'Serie municipal'!$D$2:$D$1132,E$3) -> 21.57 | F8: =SUMIFS('Serie municipal'!$H$2:$H$1132,'Serie municipal'!$B$2:$B$1132,$A8,'Serie municipal'!$G$2:$G$1132,"Deforestación",'Serie municipal'!$D$2:$D$1132,F$3) -> 7.91 | G8: =SUMIFS('Serie municipal'!$H$2:$H$1132,'Serie municipal'!$B$2:$B$1132,$A8,'Serie municipal'!$G$2:$G$1132,"Deforestación",'Serie municipal'!$D$2:$D$1132,G$3) -> 198.37 | H8: =SUMIFS('Serie municipal'!$H$2:$H$1132,'Serie municipal'!$B$2:$B$1132,$A8,'Serie municipal'!$G$2:$G$1132,"Deforestación",'Serie municipal'!$D$2:$D$1132,H$3) -> 232.58 | I8: =SUMIFS('Serie municipal'!$H$2:$H$1132,'Serie municipal'!$B$2:$B$1132,$A8,'Serie municipal'!$G$2:$G$1132,"Deforestación",'Serie municipal'!$D$2:$D$1132,I$3) -> 13.47 | ... S8: =SUMIFS('Serie municipal'!$H$2:$H$1132,'Serie municipal'!$B$2:$B$1132,$A8,'Serie municipal'!$G$2:$G$1132,"Deforestación",'Serie municipal'!$D$2:$D$1132,S$3) -> 4.06 | T8: =SUM(B8:S8) -> 768.14
A9: Chigorodó | B9: =SUMIFS('Serie municipal'!$H$2:$H$1132,'Serie municipal'!$B$2:$B$1132,$A9,'Serie municipal'!$G$2:$G$1132,"Deforestación",'Serie municipal'!$D$2:$D$1132,B$3) -> 6.79 | C9: =SUMIFS('Serie municipal'!$H$2:$H$1132,'Serie municipal'!$B$2:$B$1132,$A9,'Serie municipal'!$G$2:$G$1132,"Deforestación",'Serie municipal'!$D$2:$D$1132,C$3) -> 325.17 | D9: =SUMIFS('Serie municipal'!$H$2:$H$1132,'Serie municipal'!$B$2:$B$1132,$A9,'Serie municipal'!$G$2:$G$1132,"Deforestación",'Serie municipal'!$D$2:$D$1132,D$3) -> 140.54 | E9: =SUMIFS('Serie municipal'!$H$2:$H$1132,'Serie municipal'!$B$2:$B$1132,$A9,'Serie municipal'!$G$2:$G$1132,"Deforestación",'Serie municipal'!$D$2:$D$1132,E$3) -> 138.08 | F9: =SUMIFS('Serie municipal'!$H$2:$H$1132,'Serie municipal'!$B$2:$B$1132,$A9,'Serie municipal'!$G$2:$G$1132,"Deforestación",'Serie municipal'!$D$2:$D$1132,F$3) -> 141.73 | G9: =SUMIFS('Serie municipal'!$H$2:$H$1132,'Serie municipal'!$B$2:$B$1132,$A9,'Serie municipal'!$G$2:$G$1132,"Deforestación",'Serie municipal'!$D$2:$D$1132,G$3) -> 149.01 | H9: =SUMIFS('Serie municipal'!$H$2:$H$1132,'Serie municipal'!$B$2:$B$1132,$A9,'Serie municipal'!$G$2:$G$1132,"Deforestación",'Serie municipal'!$D$2:$D$1132,H$3) -> 106.81 | I9: =SUMIFS('Serie municipal'!$H$2:$H$1132,'Serie municipal'!$B$2:$B$1132,$A9,'Serie municipal'!$G$2:$G$1132,"Deforestación",'Serie municipal'!$D$2:$D$1132,I$3) -> 81.14 | ... S9: =SUMIFS('Serie municipal'!$H$2:$H$1132,'Serie municipal'!$B$2:$B$1132,$A9,'Serie municipal'!$G$2:$G$1132,"Deforestación",'Serie municipal'!$D$2:$D$1132,S$3) -> 47.16 | T9: =SUM(B9:S9) -> 2110.84
A10: Dabeiba | B10: =SUMIFS('Serie municipal'!$H$2:$H$1132,'Serie municipal'!$B$2:$B$1132,$A10,'Serie municipal'!$G$2:$G$1132,"Deforestación",'Serie municipal'!$D$2:$D$1132,B$3) -> 181.34 | C10: =SUMIFS('Serie municipal'!$H$2:$H$1132,'Serie municipal'!$B$2:$B$1132,$A10,'Serie municipal'!$G$2:$G$1132,"Deforestación",'Serie municipal'!$D$2:$D$1132,C$3) -> 270.42 | D10: =SUMIFS('Serie municipal'!$H$2:$H$1132,'Serie municipal'!$B$2:$B$1132,$A10,'Serie municipal'!$G$2:$G$1132,"Deforestación",'Serie municipal'!$D$2:$D$1132,D$3) -> 113.98 | E10: =SUMIFS('Serie municipal'!$H$2:$H$1132,'Serie municipal'!$B$2:$B$1132,$A10,'Serie municipal'!$G$2:$G$1132,"Deforestación",'Serie municipal'!$D$2:$D$1132,E$3) -> 174.58 | F10: =SUMIFS('Serie municipal'!$H$2:$H$1132,'Serie municipal'!$B$2:$B$1132,$A10,'Serie municipal'!$G$2:$G$1132,"Deforestación",'Serie municipal'!$D$2:$D$1132,F$3) -> 153.79 | G10: =SUMIFS('Serie municipal'!$H$2:$H$1132,'Serie municipal'!$B$2:$B$1132,$A10,'Serie municipal'!$G$2:$G$1132,"Deforestación",'Serie municipal'!$D$2:$D$1132,G$3) -> 331.11 | H10: =SUMIFS('Serie municipal'!$H$2:$H$1132,'Serie municipal'!$B$2:$B$1132,$A10,'Serie municipal'!$G$2:$G$1132,"Deforestación",'Serie municipal'!$D$2:$D$1132,H$3) -> 317.91 | I10: =SUMIFS('Serie municipal'!$H$2:$H$1132,'Serie municipal'!$B$2:$B$1132,$A10,'Serie municipal'!$G$2:$G$1132,"Deforestación",'Serie municipal'!$D$2:$D$1132,I$3) -> 392.53 | ... S10: =SUMIFS('Serie municipal'!$H$2:$H$1132,'Serie municipal'!$B$2:$B$1132,$A10,'Serie municipal'!$G$2:$G$1132,"Deforestación",'Serie municipal'!$D$2:$D$1132,S$3) -> 266.64 | T10: =SUM(B10:S10) -> 5003.33
A11: Frontino | B11: =SUMIFS('Serie municipal'!$H$2:$H$1132,'Serie municipal'!$B$2:$B$1132,$A11,'Serie municipal'!$G$2:$G$1132,"Deforestación",'Serie municipal'!$D$2:$D$1132,B$3) -> 85.78 | C11: =SUMIFS('Serie municipal'!$H$2:$H$1132,'Serie municipal'!$B$2:$B$1132,$A11,'Serie municipal'!$G$2:$G$1132,"Deforestación",'Serie municipal'!$D$2:$D$1132,C$3) -> 76.94 | D11: =SUMIFS('Serie municipal'!$H$2:$H$1132,'Serie municipal'!$B$2:$B$1132,$A11,'Serie municipal'!$G$2:$G$1132,"Deforestación",'Serie municipal'!$D$2:$D$1132,D$3) -> 43.35 | E11: =SUMIFS('Serie municipal'!$H$2:$H$1132,'Serie municipal'!$B$2:$B$1132,$A11,'Serie municipal'!$G$2:$G$1132,"Deforestación",'Serie municipal'!$D$2:$D$1132,E$3) -> 49.27 | F11: =SUMIFS('Serie municipal'!$H$2:$H$1132,'Serie municipal'!$B$2:$B$1132,$A11,'Serie municipal'!$G$2:$G$1132,"Deforestación",'Serie municipal'!$D$2:$D$1132,F$3) -> 80.69 | G11: =SUMIFS('Serie municipal'!$H$2:$H$1132,'Serie municipal'!$B$2:$B$1132,$A11,'Serie municipal'!$G$2:$G$1132,"Deforestación",'Serie municipal'!$D$2:$D$1132,G$3) -> 290.87 | H11: =SUMIFS('Serie municipal'!$H$2:$H$1132,'Serie municipal'!$B$2:$B$1132,$A11,'Serie municipal'!$G$2:$G$1132,"Deforestación",'Serie municipal'!$D$2:$D$1132,H$3) -> 306.48 | I11: =SUMIFS('Serie municipal'!$H$2:$H$1132,'Serie municipal'!$B$2:$B$1132,$A11,'Serie municipal'!$G$2:$G$1132,"Deforestación",'Serie municipal'!$D$2:$D$1132,I$3) -> 218.01 | ... S11: =SUMIFS('Serie municipal'!$H$2:$H$1132,'Serie municipal'!$B$2:$B$1132,$A11,'Serie municipal'!$G$2:$G$1132,"Deforestación",'Serie municipal'!$D$2:$D$1132,S$3) -> 211.96 | T11: =SUM(B11:S11) -> 3058.7
A12: Giraldo | B12: =SUMIFS('Serie municipal'!$H$2:$H$1132,'Serie municipal'!$B$2:$B$1132,$A12,'Serie municipal'!$G$2:$G$1132,"Deforestación",'Serie municipal'!$D$2:$D$1132,B$3) -> 1.06 | C12: =SUMIFS('Serie municipal'!$H$2:$H$1132,'Serie municipal'!$B$2:$B$1132,$A12,'Serie municipal'!$G$2:$G$1132,"Deforestación",'Serie municipal'!$D$2:$D$1132,C$3) -> 0 | D12: =SUMIFS('Serie municipal'!$H$2:$H$1132,'Serie municipal'!$B$2:$B$1132,$A12,'Serie municipal'!$G$2:$G$1132,"Deforestación",'Serie municipal'!$D$2:$D$1132,D$3) -> 0 | E12: =SUMIFS('Serie municipal'!$H$2:$H$1132,'Serie municipal'!$B$2:$B$1132,$A12,'Serie municipal'!$G$2:$G$1132,"Deforestación",'Serie municipal'!$D$2:$D$1132,E$3) -> 0 | F12: =SUMIFS('Serie municipal'!$H$2:$H$1132,'Serie municipal'!$B$2:$B$1132,$A12,'Serie municipal'!$G$2:$G$1132,"Deforestación",'Serie municipal'!$D$2:$D$1132,F$3) -> 0.97 | G12: =SUMIFS('Serie municipal'!$H$2:$H$1132,'Serie municipal'!$B$2:$B$1132,$A12,'Serie municipal'!$G$2:$G$1132,"Deforestación",'Serie municipal'!$D$2:$D$1132,G$3) -> 15.69 | H12: =SUMIFS('Serie municipal'!$H$2:$H$1132,'Serie municipal'!$B$2:$B$1132,$A12,'Serie municipal'!$G$2:$G$1132,"Deforestación",'Serie municipal'!$D$2:$D$1132,H$3) -> 18.22 | I12: =SUMIFS('Serie municipal'!$H$2:$H$1132,'Serie municipal'!$B$2:$B$1132,$A12,'Serie municipal'!$G$2:$G$1132,"Deforestación",'Serie municipal'!$D$2:$D$1132,I$3) -> 1.24 | ... S12: =SUMIFS('Serie municipal'!$H$2:$H$1132,'Serie municipal'!$B$2:$B$1132,$A12,'Serie municipal'!$G$2:$G$1132,"Deforestación",'Serie municipal'!$D$2:$D$1132,S$3) -> 13.3 | T12: =SUM(B12:S12) -> 84.98
A13: Murindó | B13: =SUMIFS('Serie municipal'!$H$2:$H$1132,'Serie municipal'!$B$2:$B$1132,$A13,'Serie municipal'!$G$2:$G$1132,"Deforestación",'Serie municipal'!$D$2:$D$1132,B$3) -> 26.23 | C13: =SUMIFS('Serie municipal'!$H$2:$H$1132,'Serie municipal'!$B$2:$B$1132,$A13,'Serie municipal'!$G$2:$G$1132,"Deforestación",'Serie municipal'!$D$2:$D$1132,C$3) -> 30.29 | D13: =SUMIFS('Serie municipal'!$H$2:$H$1132,'Serie municipal'!$B$2:$B$1132,$A13,'Serie municipal'!$G$2:$G$1132,"Deforestación",'Serie municipal'!$D$2:$D$1132,D$3) -> 325.56 | E13: =SUMIFS('Serie municipal'!$H$2:$H$1132,'Serie municipal'!$B$2:$B$1132,$A13,'Serie municipal'!$G$2:$G$1132,"Deforestación",'Serie municipal'!$D$2:$D$1132,E$3) -> 66.4 | F13: =SUMIFS('Serie municipal'!$H$2:$H$1132,'Serie municipal'!$B$2:$B$1132,$A13,'Serie municipal'!$G$2:$G$1132,"Deforestación",'Serie municipal'!$D$2:$D$1132,F$3) -> 189.09 | G13: =SUMIFS('Serie municipal'!$H$2:$H$1132,'Serie municipal'!$B$2:$B$1132,$A13,'Serie municipal'!$G$2:$G$1132,"Deforestación",'Serie municipal'!$D$2:$D$1132,G$3) -> 95.27 | H13: =SUMIFS('Serie municipal'!$H$2:$H$1132,'Serie municipal'!$B$2:$B$1132,$A13,'Serie municipal'!$G$2:$G$1132,"Deforestación",'Serie municipal'!$D$2:$D$1132,H$3) -> 19.06 | I13: =SUMIFS('Serie municipal'!$H$2:$H$1132,'Serie municipal'!$B$2:$B$1132,$A13,'Serie municipal'!$G$2:$G$1132,"Deforestación",'Serie municipal'!$D$2:$D$1132,I$3) -> 114.27 | ... S13: =SUMIFS('Serie municipal'!$H$2:$H$1132,'Serie municipal'!$B$2:$B$1132,$A13,'Serie municipal'!$G$2:$G$1132,"Deforestación",'Serie municipal'!$D$2:$D$1132,S$3) -> 87.44 | T13: =SUM(B13:S13) -> 2200.55
A14: Mutatá | B14: =SUMIFS('Serie municipal'!$H$2:$H$1132,'Serie municipal'!$B$2:$B$1132,$A14,'Serie municipal'!$G$2:$G$1132,"Deforestación",'Serie municipal'!$D$2:$D$1132,B$3) -> 285.86 | C14: =SUMIFS('Serie municipal'!$H$2:$H$1132,'Serie municipal'!$B$2:$B$1132,$A14,'Serie municipal'!$G$2:$G$1132,"Deforestación",'Serie municipal'!$D$2:$D$1132,C$3) -> 575.37 | D14: =SUMIFS('Serie municipal'!$H$2:$H$1132,'Serie municipal'!$B$2:$B$1132,$A14,'Serie municipal'!$G$2:$G$1132,"Deforestación",'Serie municipal'!$D$2:$D$1132,D$3) -> 314.65 | E14: =SUMIFS('Serie municipal'!$H$2:$H$1132,'Serie municipal'!$B$2:$B$1132,$A14,'Serie municipal'!$G$2:$G$1132,"Deforestación",'Serie municipal'!$D$2:$D$1132,E$3) -> 368.77 | F14: =SUMIFS('Serie municipal'!$H$2:$H$1132,'Serie municipal'!$B$2:$B$1132,$A14,'Serie municipal'!$G$2:$G$1132,"Deforestación",'Serie municipal'!$D$2:$D$1132,F$3) -> 558.14 | G14: =SUMIFS('Serie municipal'!$H$2:$H$1132,'Serie municipal'!$B$2:$B$1132,$A14,'Serie municipal'!$G$2:$G$1132,"Deforestación",'Serie municipal'!$D$2:$D$1132,G$3) -> 270.38 | H14: =SUMIFS('Serie municipal'!$H$2:$H$1132,'Serie municipal'!$B$2:$B$1132,$A14,'Serie municipal'!$G$2:$G$1132,"Deforestación",'Serie municipal'!$D$2:$D$1132,H$3) -> 43.32 | I14: =SUMIFS('Serie municipal'!$H$2:$H$1132,'Serie municipal'!$B$2:$B$1132,$A14,'Serie municipal'!$G$2:$G$1132,"Deforestación",'Serie municipal'!$D$2:$D$1132,I$3) -> 116.46 | ... S14: =SUMIFS('Serie municipal'!$H$2:$H$1132,'Serie municipal'!$B$2:$B$1132,$A14,'Serie municipal'!$G$2:$G$1132,"Deforestación",'Serie municipal'!$D$2:$D$1132,S$3) -> 122.98 | T14: =SUM(B14:S14) -> 4720.08
A15: Necoclí | B15: =SUMIFS('Serie municipal'!$H$2:$H$1132,'Serie municipal'!$B$2:$B$1132,$A15,'Serie municipal'!$G$2:$G$1132,"Deforestación",'Serie municipal'!$D$2:$D$1132,B$3) -> 142.45 | C15: =SUMIFS('Serie municipal'!$H$2:$H$1132,'Serie municipal'!$B$2:$B$1132,$A15,'Serie municipal'!$G$2:$G$1132,"Deforestación",'Serie municipal'!$D$2:$D$1132,C$3) -> 458.75 | D15: =SUMIFS('Serie municipal'!$H$2:$H$1132,'Serie municipal'!$B$2:$B$1132,$A15,'Serie municipal'!$G$2:$G$1132,"Deforestación",'Serie municipal'!$D$2:$D$1132,D$3) -> 504.34 | E15: =SUMIFS('Serie municipal'!$H$2:$H$1132,'Serie municipal'!$B$2:$B$1132,$A15,'Serie municipal'!$G$2:$G$1132,"Deforestación",'Serie municipal'!$D$2:$D$1132,E$3) -> 397.39 | F15: =SUMIFS('Serie municipal'!$H$2:$H$1132,'Serie municipal'!$B$2:$B$1132,$A15,'Serie municipal'!$G$2:$G$1132,"Deforestación",'Serie municipal'!$D$2:$D$1132,F$3) -> 231.62 | G15: =SUMIFS('Serie municipal'!$H$2:$H$1132,'Serie municipal'!$B$2:$B$1132,$A15,'Serie municipal'!$G$2:$G$1132,"Deforestación",'Serie municipal'!$D$2:$D$1132,G$3) -> 154.66 | H15: =SUMIFS('Serie municipal'!$H$2:$H$1132,'Serie municipal'!$B$2:$B$1132,$A15,'Serie municipal'!$G$2:$G$1132,"Deforestación",'Serie municipal'!$D$2:$D$1132,H$3) -> 68.6 | I15: =SUMIFS('Serie municipal'!$H$2:$H$1132,'Serie municipal'!$B$2:$B$1132,$A15,'Serie municipal'!$G$2:$G$1132,"Deforestación",'Serie municipal'!$D$2:$D$1132,I$3) -> 118.71 | ... S15: =SUMIFS('Serie municipal'!$H$2:$H$1132,'Serie municipal'!$B$2:$B$1132,$A15,'Serie municipal'!$G$2:$G$1132,"Deforestación",'Serie municipal'!$D$2:$D$1132,S$3) -> 37.6 | T15: =SUM(B15:S15) -> 2350.76
... A22: Vigía del Fuerte | B22: =SUMIFS('Serie municipal'!$H$2:$H$1132,'Serie municipal'!$B$2:$B$1132,$A22,'Serie municipal'!$G$2:$G$1132,"Deforestación",'Serie municipal'!$D$2:$D$1132,B$3) -> 125.38 | C22: =SUMIFS('Serie municipal'!$H$2:$H$1132,'Serie municipal'!$B$2:$B$1132,$A22,'Serie municipal'!$G$2:$G$1132,"Deforestación",'Serie municipal'!$D$2:$D$1132,C$3) -> 47.14 | D22: =SUMIFS('Serie municipal'!$H$2:$H$1132,'Serie municipal'!$B$2:$B$1132,$A22,'Serie municipal'!$G$2:$G$1132,"Deforestación",'Serie municipal'!$D$2:$D$1132,D$3) -> 101.31 | E22: =SUMIFS('Serie municipal'!$H$2:$H$1132,'Serie municipal'!$B$2:$B$1132,$A22,'Serie municipal'!$G$2:$G$1132,"Deforestación",'Serie municipal'!$D$2:$D$1132,E$3) -> 9.27 | F22: =SUMIFS('Serie municipal'!$H$2:$H$1132,'Serie municipal'!$B$2:$B$1132,$A22,'Serie municipal'!$G$2:$G$1132,"Deforestación",'Serie municipal'!$D$2:$D$1132,F$3) -> 68.74 | G22: =SUMIFS('Serie municipal'!$H$2:$H$1132,'Serie municipal'!$B$2:$B$1132,$A22,'Serie municipal'!$G$2:$G$1132,"Deforestación",'Serie municipal'!$D$2:$D$1132,G$3) -> 49.88 | H22: =SUMIFS('Serie municipal'!$H$2:$H$1132,'Serie municipal'!$B$2:$B$1132,$A22,'Serie municipal'!$G$2:$G$1132,"Deforestación",'Serie municipal'!$D$2:$D$1132,H$3) -> 25.1 | I22: =SUMIFS('Serie municipal'!$H$2:$H$1132,'Serie municipal'!$B$2:$B$1132,$A22,'Serie municipal'!$G$2:$G$1132,"Deforestación",'Serie municipal'!$D$2:$D$1132,I$3) -> 75.51 | ... S22: =SUMIFS('Serie municipal'!$H$2:$H$1132,'Serie municipal'!$B$2:$B$1132,$A22,'Serie municipal'!$G$2:$G$1132,"Deforestación",'Serie municipal'!$D$2:$D$1132,S$3) -> 12.99 | T22: =SUM(B22:S22) -> 1168.8
A23: TOTAL | B23: =SUM(B4:B22) -> 1590.3 | C23: =SUM(C4:C22) -> 3717.91 | D23: =SUM(D4:D22) -> 3021.65 | E23: =SUM(E4:E22) -> 2539.51 | F23: =SUM(F4:F22) -> 2921.36 | G23: =SUM(G4:G22) -> 3134.9 | H23: =SUM(H4:H22) -> 2273.94 | I23: =SUM(I4:I22) -> 3576.99 | ... T23: =SUM(T4:T22) -> 46845.52
A25: Periodos 2010-2012, 2018-2019 y 2023-2024: valores estimados/calibrados (2015-2016 es dato real). Escala de color blanco→rojo por intensidad.

Sheet Serie regional
A1: Periodo | B1: Año inicio | C1: Año fin | D1: Años | E1: Deforestación (ha) | F1: Ha/año | G1: Estimado | H1: Etiqueta
A2: 2000-2002 | B2: 2000 | C2: 2002 | D2: =C2-B2 -> 2 | E2: =SUMIFS('Serie municipal'!$H$2:$H$1132,'Serie municipal'!$D$2:$D$1132,A2,'Serie municipal'!$G$2:$G$1132,"Deforestación") -> 1590.3 | F2: =E2/D2 -> 795.15 | G2: No | H2: =A2&IF(G2="Sí","*","") -> 2000-2002
A3: 2002-2004 | B3: 2002 | C3: 2004 | D3: =C3-B3 -> 2 | E3: =SUMIFS('Serie municipal'!$H$2:$H$1132,'Serie municipal'!$D$2:$D$1132,A3,'Serie municipal'!$G$2:$G$1132,"Deforestación") -> 3717.91 | F3: =E3/D3 -> 1858.955 | G3: No | H3: =A3&IF(G3="Sí","*","") -> 2002-2004
A4: 2004-2006 | B4: 2004 | C4: 2006 | D4: =C4-B4 -> 2 | E4: =SUMIFS('Serie municipal'!$H$2:$H$1132,'Serie municipal'!$D$2:$D$1132,A4,'Serie municipal'!$G$2:$G$1132,"Deforestación") -> 3021.65 | F4: =E4/D4 -> 1510.825 | G4: No | H4: =A4&IF(G4="Sí","*","") -> 2004-2006
A5: 2006-2008 | B5: 2006 | C5: 2008 | D5: =C5-B5 -> 2 | E5: =SUMIFS('Serie municipal'!$H$2:$H$1132,'Serie municipal'!$D$2:$D$1132,A5,'Serie municipal'!$G$2:$G$1132,"Deforestación") -> 2539.51 | F5: =E5/D5 -> 1269.755 | G5: No | H5: =A5&IF(G5="Sí","*","") -> 2006-2008
A6: 2008-2010 | B6: 2008 | C6: 2010 | D6: =C6-B6 -> 2 | E6: =SUMIFS('Serie municipal'!$H$2:$H$1132,'Serie municipal'!$D$2:$D$1132,A6,'Serie municipal'!$G$2:$G$1132,"Deforestación") -> 2921.36 | F6: =E6/D6 -> 1460.68 | G6: No | H6: =A6&IF(G6="Sí","*","") -> 2008-2010
A7: 2010-2012 | B7: 2010 | C7: 2012 | D7: =C7-B7 -> 2 | E7: =SUMIFS('Serie municipal'!$H$2:$H$1132,'Serie municipal'!$D$2:$D$1132,A7,'Serie municipal'!$G$2:$G$1132,"Deforestación") -> 3134.9 | F7: =E7/D7 -> 1567.45 | G7: Sí | H7: =A7&IF(G7="Sí","*","") -> 2010-2012*
A8: 2012-2013 | B8: 2012 | C8: 2013 | D8: =C8-B8 -> 1 | E8: =SUMIFS('Serie municipal'!$H$2:$H$1132,'Serie municipal'!$D$2:$D$1132,A8,'Serie municipal'!$G$2:$G$1132,"Deforestación") -> 2273.94 | F8: =E8/D8 -> 2273.94 | G8: No | H8: =A8&IF(G8="Sí","*","") -> 2012-2013
A9: 2013-2014 | B9: 2013 | C9: 2014 | D9: =C9-B9 -> 1 | E9: =SUMIFS('Serie municipal'!$H$2:$H$1132,'Serie municipal'!$D$2:$D$1132,A9,'Serie municipal'!$G$2:$G$1132,"Deforestación") -> 3576.99 | F9: =E9/D9 -> 3576.99 | G9: No | H9: =A9&IF(G9="Sí","*","") -> 2013-2014
A10: 2014-2015 | B10: 2014 | C10: 2015 | D10: =C10-B10 -> 1 | E10: =SUMIFS('Serie municipal'!$H$2:$H$1132,'Serie municipal'!$D$2:$D$1132,A10,'Serie municipal'!$G$2:$G$1132,"Deforestación") -> 2887.49 | F10: =E10/D10 -> 2887.49 | G10: No | H10: =A10&IF(G10="Sí","*","") -> 2014-2015
A11: 2015-2016 | B11: 2015 | C11: 2016 | D11: =C11-B11 -> 1 | E11: =SUMIFS('Serie municipal'!$H$2:$H$1132,'Serie municipal'!$D$2:$D$1132,A11,'Serie municipal'!$G$2:$G$1132,"Deforestación") -> 5771.04 | F11: =E11/D11 -> 5771.04 | G11: No | H11: =A11&IF(G11="Sí","*","") -> 2015-2016
A12: 2016-2017 | B12: 2016 | C12: 2017 | D12: =C12-B12 -> 1 | E12: =SUMIFS('Serie municipal'!$H$2:$H$1132,'Serie municipal'!$D$2:$D$1132,A12,'Serie municipal'!$G$2:$G$1132,"Deforestación") -> 3938.39 | F12: =E12/D12 -> 3938.39 | G12: No | H12: =A12&IF(G12="Sí","*","") -> 2016-2017
A13: 2017-2018 | B13: 2017 | C13: 2018 | D13: =C13-B13 -> 1 | E13: =SUMIFS('Serie municipal'!$H$2:$H$1132,'Serie municipal'!$D$2:$D$1132,A13,'Serie municipal'!$G$2:$G$1132,"Deforestación") -> 1765.16 | F13: =E13/D13 -> 1765.16 | G13: No | H13: =A13&IF(G13="Sí","*","") -> 2017-2018
... A19: 2023-2024 | B19: 2023 | C19: 2024 | D19: =C19-B19 -> 1 | E19: =SUMIFS('Serie municipal'!$H$2:$H$1132,'Serie municipal'!$D$2:$D$1132,A19,'Serie municipal'!$G$2:$G$1132,"Deforestación") -> 1596.81 | F19: =E19/D19 -> 1596.81 | G19: Sí | H19: =A19&IF(G19="Sí","*","") -> 2023-2024*
D20: TOTAL | E20: =SUM(E2:E19) -> 46845.52
A21: * Periodo estimado/calibrado (sin fuente municipal directa en el paquete original). Ver Diccionario.

Sheet Aux
A1: Hoja auxiliar de cálculos (totales por municipio y ranking)
A3: Municipio | B3: Territorial | C3: Total 2000-2024 (ha) | D3: Ha/año prom. | F3: Pos. | G3: Ranking municipio | H3: Total (ha)
A4: Abriaquí | B4: Nutibara | C4: =SUMIFS('Serie municipal'!$H$2:$H$1132,'Serie municipal'!$B$2:$B$1132,A4,'Serie municipal'!$G$2:$G$1132,"Deforestación") -> 311.54 | D4: =C4/24 -> 12.980833 | F4: 1 | G4: =INDEX($A$4:$A$22,MATCH(H4,$C$4:$C$22,0)) -> Turbo | H4: =LARGE($C$4:$C$22,F4) -> 13308.94
A5: Apartadó | B5: Centro | C5: =SUMIFS('Serie municipal'!$H$2:$H$1132,'Serie municipal'!$B$2:$B$1132,A5,'Serie municipal'!$G$2:$G$1132,"Deforestación") -> 2271.64 | D5: =C5/24 -> 94.651667 | F5: 2 | G5: =INDEX($A$4:$A$22,MATCH(H5,$C$4:$C$22,0)) -> Urrao | H5: =LARGE($C$4:$C$22,F5) -> 5759.44
A6: Arboletes | B6: Caribe | C6: =SUMIFS('Serie municipal'!$H$2:$H$1132,'Serie municipal'!$B$2:$B$1132,A6,'Serie municipal'!$G$2:$G$1132,"Deforestación") -> 537.14 | D6: =C6/24 -> 22.380833 | F6: 3 | G6: =INDEX($A$4:$A$22,MATCH(H6,$C$4:$C$22,0)) -> Dabeiba | H6: =LARGE($C$4:$C$22,F6) -> 5003.33
A7: Carepa | B7: Centro | C7: =SUMIFS('Serie municipal'!$H$2:$H$1132,'Serie municipal'!$B$2:$B$1132,A7,'Serie municipal'!$G$2:$G$1132,"Deforestación") -> 2026.08 | D7: =C7/24 -> 84.42 | F7: 4 | G7: =INDEX($A$4:$A$22,MATCH(H7,$C$4:$C$22,0)) -> Mutatá | H7: =LARGE($C$4:$C$22,F7) -> 4720.08
A8: Cañasgordas | B8: Nutibara | C8: =SUMIFS('Serie municipal'!$H$2:$H$1132,'Serie municipal'!$B$2:$B$1132,A8,'Serie municipal'!$G$2:$G$1132,"Deforestación") -> 768.14 | D8: =C8/24 -> 32.005833 | F8: 5 | G8: =INDEX($A$4:$A$22,MATCH(H8,$C$4:$C$22,0)) -> Frontino | H8: =LARGE($C$4:$C$22,F8) -> 3058.7
A9: Chigorodó | B9: Centro | C9: =SUMIFS('Serie municipal'!$H$2:$H$1132,'Serie municipal'!$B$2:$B$1132,A9,'Serie municipal'!$G$2:$G$1132,"Deforestación") -> 2110.84 | D9: =C9/24 -> 87.951667 | F9: 6 | G9: =INDEX($A$4:$A$22,MATCH(H9,$C$4:$C$22,0)) -> Necoclí | H9: =LARGE($C$4:$C$22,F9) -> 2350.76
A10: Dabeiba | B10: Nutibara | C10: =SUMIFS('Serie municipal'!$H$2:$H$1132,'Serie municipal'!$B$2:$B$1132,A10,'Serie municipal'!$G$2:$G$1132,"Deforestación") -> 5003.33 | D10: =C10/24 -> 208.47208 | F10: 7 | G10: =INDEX($A$4:$A$22,MATCH(H10,$C$4:$C$22,0)) -> Apartadó | H10: =LARGE($C$4:$C$22,F10) -> 2271.64
A11: Frontino | B11: Nutibara | C11: =SUMIFS('Serie municipal'!$H$2:$H$1132,'Serie municipal'!$B$2:$B$1132,A11,'Serie municipal'!$G$2:$G$1132,"Deforestación") -> 3058.7 | D11: =C11/24 -> 127.44583 | F11: 8 | G11: =INDEX($A$4:$A$22,MATCH(H11,$C$4:$C$22,0)) -> Murindó | H11: =LARGE($C$4:$C$22,F11) -> 2200.55
A12: Giraldo | B12: Nutibara | C12: =SUMIFS('Serie municipal'!$H$2:$H$1132,'Serie municipal'!$B$2:$B$1132,A12,'Serie municipal'!$G$2:$G$1132,"Deforestación") -> 84.98 | D12: =C12/24 -> 3.5408333 | F12: 9 | G12: =INDEX($A$4:$A$22,MATCH(H12,$C$4:$C$22,0)) -> Chigorodó | H12: =LARGE($C$4:$C$22,F12) -> 2110.84
A13: Murindó | B13: Atrato | C13: =SUMIFS('Serie municipal'!$H$2:$H$1132,'Serie municipal'!$B$2:$B$1132,A13,'Serie municipal'!$G$2:$G$1132,"Deforestación") -> 2200.55 | D13: =C13/24 -> 91.689583 | F13: 10 | G13: =INDEX($A$4:$A$22,MATCH(H13,$C$4:$C$22,0)) -> Carepa | H13: =LARGE($C$4:$C$22,F13) -> 2026.08
A14: Mutatá | B14: Centro | C14: =SUMIFS('Serie municipal'!$H$2:$H$1132,'Serie municipal'!$B$2:$B$1132,A14,'Serie municipal'!$G$2:$G$1132,"Deforestación") -> 4720.08 | D14: =C14/24 -> 196.67
A15: Necoclí | B15: Caribe | C15: =SUMIFS('Serie municipal'!$H$2:$H$1132,'Serie municipal'!$B$2:$B$1132,A15,'Serie municipal'!$G$2:$G$1132,"Deforestación") -> 2350.76 | D15: =C15/24 -> 97.948333
A16: Peque | B16: Nutibara | C16: =SUMIFS('Serie municipal'!$H$2:$H$1132,'Serie municipal'!$B$2:$B$1132,A16,'Serie municipal'!$G$2:$G$1132,"Deforestación") -> 401.16 | D16: =C16/24 -> 16.715 | J16: Territorial | K16: Total (ha)
A17: San Juan de Urabá | B17: Caribe | C17: =SUMIFS('Serie municipal'!$H$2:$H$1132,'Serie municipal'!$B$2:$B$1132,A17,'Serie municipal'!$G$2:$G$1132,"Deforestación") -> 61.96 | D17: =C17/24 -> 2.5816667 | J17: Caribe | K17: =SUMIFS('Serie municipal'!$H$2:$H$1132,'Serie municipal'!$C$2:$C$1132,J17,'Serie municipal'!$G$2:$G$1132,"Deforestación") -> 3147.14
A18: San Pedro de Urabá | B18: Caribe | C18: =SUMIFS('Serie municipal'!$H$2:$H$1132,'Serie municipal'!$B$2:$B$1132,A18,'Serie municipal'!$G$2:$G$1132,"Deforestación") -> 197.28 | D18: =C18/24 -> 8.22 | J18: Centro | K18: =SUMIFS('Serie municipal'!$H$2:$H$1132,'Serie municipal'!$C$2:$C$1132,J18,'Serie municipal'!$G$2:$G$1132,"Deforestación") -> 24437.58
A19: Turbo | B19: Centro | C19: =SUMIFS('Serie municipal'!$H$2:$H$1132,'Serie municipal'!$B$2:$B$1132,A19,'Serie municipal'!$G$2:$G$1132,"Deforestación") -> 13308.94 | D19: =C19/24 -> 554.53917 | J19: Atrato | K19: =SUMIFS('Serie municipal'!$H$2:$H$1132,'Serie municipal'!$C$2:$C$1132,J19,'Serie municipal'!$G$2:$G$1132,"Deforestación") -> 3369.35
A20: Uramita | B20: Nutibara | C20: =SUMIFS('Serie municipal'!$H$2:$H$1132,'Serie municipal'!$B$2:$B$1132,A20,'Serie municipal'!$G$2:$G$1132,"Deforestación") -> 504.16 | D20: =C20/24 -> 21.006667 | J20: Nutibara | K20: =SUMIFS('Serie municipal'!$H$2:$H$1132,'Serie municipal'!$C$2:$C$1132,J20,'Serie municipal'!$G$2:$G$1132,"Deforestación") -> 10132.01
A21: Urrao | B21: Urrao | C21: =SUMIFS('Serie municipal'!$H$2:$H$1132,'Serie municipal'!$B$2:$B$1132,A21,'Serie municipal'!$G$2:$G$1132,"Deforestación") -> 5759.44 | D21: =C21/24 -> 239.97667 | J21: Urrao | K21: =SUMIFS('Serie municipal'!$H$2:$H$1132,'Serie municipal'!$C$2:$C$1132,J21,'Serie municipal'!$G$2:$G$1132,"Deforestación") -> 5759.44
A22: Vigía del Fuerte | B22: Atrato | C22: =SUMIFS('Serie municipal'!$H$2:$H$1132,'Serie municipal'!$B$2:$B$1132,A22,'Serie municipal'!$G$2:$G$1132,"Deforestación") -> 1168.8 | D22: =C22/24 -> 48.7

Sheet Dinámica bosque
A1: codigo_dane | B1: municipio | C1: subregion | D1: periodo | E1: ano_inicio | F1: ano_fin | G1: n_anos | H1: bosque_estable_ha | I1: no_bosque_ha | J1: regeneracion_ha | K1: sin_informacion_ha | L1: deforestacion_ha | M1: area_con_informacion_ha | N1: pct_cobertura_bosque | O1: bosque_estable_previo_ha | P1: periodo_bosque_previo | Q1: tasa_perdida_relativa | R1: cambio_neto_ha | S1: fuente | T1: calidad_fuente | U1: estimado
A2: 5004 | B2: Abriaquí | C2: Nutibara | D2: 2000-2002 | E2: 2000 | F2: 2002 | G2: 2 | H2: 13423.94 | I2: 16259.23 | L2: 9.05 | M2: 29692.22 | N2: 45.21 | R2: 9.05 | S2: excel | T2: excel_tabla | U2: FALSE
A3: 5004 | B3: Abriaquí | C3: Nutibara | D3: 2002-2004 | E3: 2002 | F3: 2004 | G3: 2 | H3: 13395.8 | I3: 16258.2 | L3: 8.99 | M3: 29663 | N3: 45.16 | O3: 13423.94 | P3: 2000-2002 | Q3: 0.0335 | R3: 8.99 | S3: shapefile | T3: shapefile_geometria | U3: FALSE
A4: 5004 | B4: Abriaquí | C4: Nutibara | D4: 2004-2006 | E4: 2004 | F4: 2006 | G4: 2 | H4: 13395.04 | I4: 16267.96 | M4: 29663 | N4: 45.16 | O4: 13395.8 | P4: 2002-2004 | R4: 0 | S4: shapefile | T4: shapefile_geometria | U4: FALSE
A5: 5004 | B5: Abriaquí | C5: Nutibara | D5: 2006-2008 | E5: 2006 | F5: 2008 | G5: 2 | H5: 13394.75 | I5: 16266.78 | L5: 1.47 | M5: 29663 | N5: 45.16 | O5: 13395.04 | P5: 2004-2006 | Q5: 0.0055 | R5: 1.47 | S5: shapefile | T5: shapefile_geometria | U5: FALSE
A6: 5004 | B6: Abriaquí | C6: Nutibara | D6: 2008-2010 | E6: 2008 | F6: 2010 | G6: 2 | H6: 13429.01 | I6: 16225.36 | K6: 5.67 | L6: 2.95 | M6: 29657.32 | N6: 45.28 | O6: 13394.75 | P6: 2006-2008 | Q6: 0.011 | R6: 2.95 | S6: shapefile | T6: shapefile_geometria | U6: FALSE
A7: 5004 | B7: Abriaquí | C7: Nutibara | D7: 2010-2012 | E7: 2010 | F7: 2012 | G7: 2 | L7: 74.44 | O7: 13429.01 | P7: 2008-2010 | Q7: 0.2772 | R7: 74.44 | S7: estimado-calibrado-rat | T7: solo_defo_estimada | U7: TRUE
A8: 5004 | B8: Abriaquí | C8: Nutibara | D8: 2012-2013 | E8: 2012 | F8: 2013 | G8: 1 | H8: 13505.37 | I8: 16085.67 | K8: 5.95 | L8: 87.29 | M8: 29678.32 | N8: 45.51 | O8: 13429.01 | P8: 2008-2010 | Q8: 0.65 | R8: 87.29 | S8: raster | T8: raster_zonal | U8: FALSE
A9: 5004 | B9: Abriaquí | C9: Nutibara | D9: 2013-2014 | E9: 2013 | F9: 2014 | G9: 1 | H9: 13485.89 | I9: 16189.26 | L9: 15.25 | M9: 29690.4 | N9: 45.42 | O9: 13505.37 | P9: 2012-2013 | Q9: 0.1129 | R9: 15.25 | S9: shapefile | T9: shapefile_geometria | U9: FALSE
A10: 5004 | B10: Abriaquí | C10: Nutibara | D10: 2014-2015 | E10: 2014 | F10: 2015 | G10: 1 | H10: 13453.08 | I10: 16184 | L10: 17.09 | M10: 29654.16 | N10: 45.37 | O10: 13485.89 | P10: 2013-2014 | Q10: 0.1267 | R10: 17.09 | S10: excel | T10: excel_tabla | U10: FALSE
A11: 5004 | B11: Abriaquí | C11: Nutibara | D11: 2015-2016 | E11: 2015 | F11: 2016 | G11: 1 | L11: 25.09 | O11: 13453.08 | P11: 2014-2015 | Q11: 0.1865 | R11: 25.09 | S11: cuencas-calibrado | T11: solo_defo_estimada | U11: TRUE
A12: 5004 | B12: Abriaquí | C12: Nutibara | D12: 2016-2017 | E12: 2016 | F12: 2017 | G12: 1 | H12: 13665 | I12: 15962.38 | L12: 35.66 | M12: 29663.04 | N12: 46.07 | O12: 13453.08 | P12: 2014-2015 | Q12: 0.2651 | R12: 35.66 | S12: shapefile | T12: shapefile_geometria | U12: FALSE
A13: 5004 | B13: Abriaquí | C13: Nutibara | D13: 2017-2018 | E13: 2017 | F13: 2018 | G13: 1 | H13: 13654.53 | I13: 16002.85 | K13: 1.32 | L13: 4.28 | M13: 29661.66 | N13: 46.03 | O13: 13665 | P13: 2016-2017 | Q13: 0.0313 | R13: 4.28 | S13: shapefile | T13: shapefile_geometria | U13: FALSE
A14: 5004 | B14: Abriaquí | C14: Nutibara | D14: 2018-2019 | E14: 2018 | F14: 2019 | G14: 1 | L14: 2.7 | O14: 13654.53 | P14: 2017-2018 | Q14: 0.0198 | R14: 2.7 | S14: estimado | T14: solo_defo_estimada | U14: TRUE
A15: 5004 | B15: Abriaquí | C15: Nutibara | D15: 2019-2020 | E15: 2019 | F15: 2020 | G15: 1 | H15: 13617.96 | I15: 16043.91 | L15: 1.12 | M15: 29662.99 | N15: 45.91 | O15: 13654.53 | P15: 2017-2018 | Q15: 0.0082 | R15: 1.12 | S15: shapefile | T15: shapefile_geometria | U15: FALSE
A16: 5004 | B16: Abriaquí | C16: Nutibara | D16: 2020-2021 | E16: 2020 | F16: 2021 | G16: 1 | H16: 13617.95 | I16: 16045.04 | M16: 29662.99 | N16: 45.91 | O16: 13617.96 | P16: 2019-2020 | R16: 0 | S16: shapefile | T16: shapefile_geometria | U16: FALSE
A17: 5004 | B17: Abriaquí | C17: Nutibara | D17: 2021-2022 | E17: 2021 | F17: 2022 | G17: 1 | H17: 13601.07 | I17: 16056.07 | L17: 5.77 | M17: 29662.91 | N17: 45.85 | O17: 13617.95 | P17: 2020-2021 | Q17: 0.0423 | R17: 5.77 | S17: shapefile | T17: shapefile_geometria | U17: FALSE
A18: 5004 | B18: Abriaquí | C18: Nutibara | D18: 2022-2023 | E18: 2022 | F18: 2023 | G18: 1 | H18: 13573.16 | I18: 16081.81 | L18: 8.22 | M18: 29663.19 | N18: 45.76 | O18: 13601.07 | P18: 2021-2022 | Q18: 0.0604 | R18: 8.22 | S18: shapefile | T18: shapefile_geometria | U18: FALSE
A19: 5004 | B19: Abriaquí | C19: Nutibara | D19: 2023-2024 | E19: 2023 | F19: 2024 | G19: 1 | L19: 12.14 | O19: 13573.16 | P19: 2022-2023 | Q19: 0.0894 | R19: 12.14 | S19: estimado | T19: solo_defo_estimada | U19: TRUE
A20: 5045 | B20: Apartadó | C20: Centro | D20: 2000-2002 | E20: 2000 | F20: 2002 | G20: 2 | H20: 17703.41 | I20: 35423.51 | K20: 252.81 | L20: 16.41 | M20: 53143.34 | N20: 33.31 | R20: 16.41 | S20: excel | T20: excel_tabla | U20: FALSE
A21: 5045 | B21: Apartadó | C21: Centro | D21: 2002-2004 | E21: 2002 | F21: 2004 | G21: 2 | H21: 17674.26 | I21: 35282.73 | K21: 284.07 | L21: 40.27 | M21: 52997.26 | N21: 33.35 | O21: 17703.41 | P21: 2000-2002 | Q21: 0.1137 | R21: 40.27 | S21: shapefile | T21: shapefile_geometria | U21: FALSE
A22: 5045 | B22: Apartadó | C22: Centro | D22: 2004-2006 | E22: 2004 | F22: 2006 | G22: 2 | H22: 17662.97 | I22: 35376.58 | K22: 179.33 | L22: 62.23 | M22: 53101.78 | N22: 33.26 | O22: 17674.26 | P22: 2002-2004 | Q22: 0.176 | R22: 62.23 | S22: shapefile | T22: shapefile_geometria | U22: FALSE
A23: 5045 | B23: Apartadó | C23: Centro | D23: 2006-2008 | E23: 2006 | F23: 2008 | G23: 2 | H23: 17510.36 | I23: 35442.98 | K23: 128.05 | L23: 199.72 | M23: 53153.05 | N23: 32.94 | O23: 17662.97 | P23: 2004-2006 | Q23: 0.5654 | R23: 199.72 | S23: shapefile | T23: shapefile_geometria | U23: FALSE
A24: 5045 | B24: Apartadó | C24: Centro | D24: 2008-2010 | E24: 2008 | F24: 2010 | G24: 2 | H24: 17452.83 | I24: 35406.96 | K24: 318.51 | L24: 102.76 | M24: 52962.56 | N24: 32.95 | O24: 17510.36 | P24: 2006-2008 | Q24: 0.2934 | R24: 102.76 | S24: shapefile | T24: shapefile_geometria | U24: FALSE
A25: 5045 | B25: Apartadó | C25: Centro | D25: 2010-2012 | E25: 2010 | F25: 2012 | G25: 2 | L25: 88.39 | O25: 17452.83 | P25: 2008-2010 | Q25: 0.2532 | R25: 88.39 | S25: estimado-calibrado-rat | T25: solo_defo_estimada | U25: TRUE
A26: 5045 | B26: Apartadó | C26: Centro | D26: 2012-2013 | E26: 2012 | F26: 2013 | G26: 1 | H26: 18613.45 | I26: 34595.66 | K26: 54.01 | L26: 54.01 | M26: 53263.12 | N26: 34.95 | O26: 17452.83 | P26: 2008-2010 | Q26: 0.3095 | R26: 54.01 | S26: raster | T26: raster_zonal | U26: FALSE
A27: 5045 | B27: Apartadó | C27: Centro | D27: 2013-2014 | E27: 2013 | F27: 2014 | G27: 1 | H27: 16768.01 | I27: 34764.97 | K27: 1432.31 | L27: 410.94 | M27: 51943.92 | N27: 32.28 | O27: 18613.45 | P27: 2012-2013 | Q27: 2.2078 | R27: 410.94 | S27: shapefile | T27: shapefile_geometria | U27: FALSE
A28: 5045 | B28: Apartadó | C28: Centro | D28: 2014-2015 | E28: 2014 | F28: 2015 | G28: 1 | H28: 17953.49 | I28: 34905.96 | K28: 361.69 | L28: 54.57 | M28: 52914.02 | N28: 33.93 | O28: 16768.01 | P28: 2013-2014 | Q28: 0.3255 | R28: 54.57 | S28: excel | T28: excel_tabla | U28: FALSE
A29: 5045 | B29: Apartadó | C29: Centro | D29: 2015-2016 | E29: 2015 | F29: 2016 | G29: 1 | L29: 367.41 | O29: 17953.49 | P29: 2014-2015 | Q29: 2.0465 | R29: 367.41 | S29: cuencas-calibrado | T29: solo_defo_estimada | U29: TRUE
A30: 5045 | B30: Apartadó | C30: Centro | D30: 2016-2017 | E30: 2016 | F30: 2017 | G30: 1 | H30: 17473.42 | I30: 35185.86 | J30: 12.92 | K30: 366.05 | L30: 241.81 | M30: 52914.02 | N30: 33.02 | O30: 17953.49 | P30: 2014-2015 | Q30: 1.3469 | R30: 228.89 | S30: shapefile | T30: shapefile_geometria | U30: FALSE
A31: 5045 | B31: Apartadó | C31: Centro | D31: 2017-2018 | E31: 2017 | F31: 2018 | G31: 1 | H31: 15722.06 | I31: 37331.57 | J31: 1.63 | K31: 69.74 | L31: 154.92 | M31: 53210.19 | N31: 29.55 | O31: 17473.42 | P31: 2016-2017 | Q31: 0.8866 | R31: 153.28 | S31: shapefile | T31: shapefile_geometria | U31: FALSE
A32: 5045 | B32: Apartadó | C32: Centro | D32: 2018-2019 | E32: 2018 | F32: 2019 | G32: 1 | L32: 97.73 | O32: 15722.06 | P32: 2017-2018 | Q32: 0.6216 | R32: 97.73 | S32: estimado | T32: solo_defo_estimada | U32: TRUE
A33: 5045 | B33: Apartadó | C33: Centro | D33: 2019-2020 | E33: 2019 | F33: 2020 | G33: 1 | H33: 15600.86 | I33: 37638.29 | K33: 0.91 | L33: 40.54 | M33: 53279.69 | N33: 29.28 | O33: 15722.06 | P33: 2017-2018 | Q33: 0.2579 | R33: 40.54 | S33: shapefile | T33: shapefile_geometria | U33: FALSE
A34: 5045 | B34: Apartadó | C34: Centro | D34: 2020-2021 | E34: 2020 | F34: 2021 | G34: 1 | H34: 15554.68 | I34: 37677.1 | K34: 14.02 | L34: 34.8 | M34: 53266.59 | N34: 29.2 | O34: 15600.86 | P34: 2019-2020 | Q34: 0.2231 | R34: 34.8 | S34: shapefile | T34: shapefile_geometria | U34: FALSE
A35: 5045 | B35: Apartadó | C35: Centro | D35: 2021-2022 | E35: 2021 | F35: 2022 | G35: 1 | H35: 15379.16 | I35: 37740.52 | K35: 39.64 | L35: 121.26 | M35: 53240.95 | N35: 28.89 | O35: 15554.68 | P35: 2020-2021 | Q35: 0.7796 | R35: 121.26 | S35: shapefile | T35: shapefile_geometria | U35: FALSE
A36: 5045 | B36: Apartadó | C36: Centro | D36: 2022-2023 | E36: 2022 | F36: 2023 | G36: 1 | H36: 15029.81 | I36: 38204.77 | L36: 45.93 | M36: 53280.51 | N36: 28.21 | O36: 15379.16 | P36: 2021-2022 | Q36: 0.2986 | R36: 45.93 | S36: shapefile | T36: shapefile_geometria | U36: FALSE
A37: 5045 | B37: Apartadó | C37: Centro | D37: 2023-2024 | E37: 2023 | F37: 2024 | G37: 1 | L37: 78.45 | O37: 15029.81 | P37: 2022-2023 | Q37: 0.522 | R37: 78.45 | S37: estimado | T37: solo_defo_estimada | U37: TRUE
A38: 5051 | B38: Arboletes | C38: Caribe | D38: 2000-2002 | E38: 2000 | F38: 2002 | G38: 2 | H38: 1237.91 | I38: 72954.65 | K38: 0.75 | L38: 2.68 | M38: 74195.24 | N38: 1.67 | R38: 2.68 | S38: excel | T38: excel_tabla | U38: FALSE
A39: 5051 | B39: Arboletes | C39: Caribe | D39: 2002-2004 | E39: 2002 | F39: 2004 | G39: 2 | H39: 1227.54 | I39: 72830.89 | L39: 6.56 | M39: 74064.99 | N39: 1.66 | O39: 1237.91 | P39: 2000-2002 | Q39: 0.2649 | R39: 6.56 | S39: shapefile | T39: shapefile_geometria | U39: FALSE
A40: 5051 | B40: Arboletes | C40: Caribe | D40: 2004-2006 | E40: 2004 | F40: 2006 | G40: 2 | H40: 1067.58 | I40: 72821.66 | J40: 19.05 | L40: 156.71 | M40: 74064.99 | N40: 1.44 | O40: 1227.54 | P40: 2002-2004 | Q40: 6.3829 | R40: 137.66 | S40: shapefile | T40: shapefile_geometria | U40: FALSE
...

Sheet Hallazgos
A1: Tema | B1: Hallazgo | C1: Cifra | D1: Unidad | E1: Periodo | F1: Descripción
A2: territorios_etnicos | B2: La deforestación se desplaza hacia territorios étnicos | C2: 40.6 | D2: % de la deforestación mapeada | E2: 2019-2023 | F2: En 2002-2010 los resguardos indígenas y consejos comunitarios concentraban el 16,6% de la deforestación mapeada; en 2019-2023 concentran el 40,6%. La presión se movió hacia los territorios colectivos mientras el resto de la jurisdicción desacelera.
A3: dinamica_bosque | B3: La jurisdicción perdió 37.809 ha de bosque estable | C3: 37809 | D3: ha (2000-2002 → 2022-2023) | E3: 2000-2023 | F3: El bosque estable pasó de 908.114 ha a 870.305 ha entre los periodos 2000-2002 y 2022-2023: una pérdida neta del 4,2% del bosque de la jurisdicción, medida con las mismas fuentes municipales en ambos extremos.
A4: fragmentacion | B4: 79% de la pérdida ocurre en frentes persistentes | C4: 78.9 | D4: % de ha en celdas recurrentes | E4: 2002-2023 | F4: 1.411 celdas de 2×2 km registran deforestación en 3 o más periodos y concentran el 78,9% de las hectáreas deforestadas mapeadas. No son eventos dispersos: son frentes activos y localizables, priorizables para control.
A5: dinamica_bosque | B5: Turbo pierde más bosque; Carepa, la mayor fracción | C5: 18424 | D5: ha de bosque perdidas (Turbo) | E5: 2000-2023 | F5: Turbo perdió 18.424 ha de bosque estable (-24,6% de su bosque de 2000). En proporción, Carepa es el caso más crítico: conserva solo el 56,8% de su bosque inicial (-43,2%). Necoclí (-23,8%) y Chigorodó (-12,6%) completan el cuadro del eje bananero.
A6: areas_protegidas | B6: 3.362 ha deforestadas dentro de áreas protegidas | C6: 3362 | D6: ha (12,6% de lo mapeado) | E6: 2002-2023 | F6: En los 10 periodos comparables, el 12,6% de la deforestación mapeada ocurrió dentro de áreas protegidas. El DRMI Serranía de Abibe concentra 1.903 ha (57% del total en AP), con pico de 585 ha en 2015-2016; le siguen la RFPN Carauta (514 ha) y el PNN Las Orquídeas (334 ha).
A7: dinamica_bosque | B7: La regeneración solo compensa el 2% de la pérdida | C7: 2.1 | D7: % de la deforestación medida | E7: 2000-2023 | F7: En los periodos con medición directa se regeneraron 726 ha frente a 34.542 ha deforestadas: una relación de 1 a 48. Arboletes (18,8%) y Urrao (9,6%) son los únicos municipios donde la regeneración supera el 5% de su pérdida.
A8: cuencas | B8: La cuenca del río León es la más golpeada | C8: 6333 | D8: ha deforestadas | E8: 2000-2023 | F8: De las 7 cuencas monitoreadas (39% de la jurisdicción), la del río León acumula 6.333 ha deforestadas (2,9% de su superficie) con tendencia a empeorar. Le sigue Turbo-Currulao con 2.604 ha. Son cuencas abastecedoras del eje bananero.
A9: territorios_etnicos | B9: El pueblo Embera Katío concentra la pérdida en resguardos | C9: 3478 | D9: ha (77% de la pérdida en resguardos) | E9: 2002-2023 | F9: De las 4.513 ha deforestadas en resguardos con medición de área, 3.478 ha corresponden a territorios del pueblo Embera Katío. Los resguardos de Murindó (583 ha), Chaquenodá (558 ha) y Andabú (421 ha) encabezan el ranking.
A10: fragmentacion | B10: Frentes activos 11 de 12 periodos en Mutatá y Dabeiba | C10: 11 | D10: periodos con deforestación (máx. observado) | E10: 2002-2023 | F10: Las celdas más recurrentes de la jurisdicción (piedemonte de Mutatá y Dabeiba, eje de la vía al mar) registran deforestación en 11 de los 12 periodos mapeados, con hasta 136 ha acumuladas por celda de 400 ha. Urrao (249), Turbo (221) y Dabeiba (203) tienen más celdas persistentes.
A11: territorios_etnicos | B11: ACIA (Medio Atrato): el territorio colectivo más afectado | C11: 1255 | D11: ha deforestadas | E11: 2002-2023 | F11: El Consejo Comunitario Mayor del Medio Atrato acumula 1.255 ha deforestadas, el 55% de la pérdida en consejos comunitarios (2.269 ha). En proporción de su enorme territorio (174.778 ha) es un 0,7%, pero su tendencia acompaña la aceleración del Atrato.
A12: fragmentacion | B12: Deforestación atomizada: 19.023 parches, mediana 1 ha | C12: 19023 | D12: parches en 12 periodos (incluye < 1 ha) | E12: 2002-2023 | F12: El 96% de los parches mide menos de 5 ha (70% del área); solo el 1,2% supera 10 ha pero aporta el 19% del área. El tamaño medio de parche es pequeño (~1,6 ha; mediana 0,95 ha) e incluye ahora los focos de menos de 1 ha: el patrón es de colonización hormiga, no de grandes praderizaciones — con la excepción de Turbo (parche máximo de 738 ha).
A13: dinamica_bosque | B13: Caribe y Centro desaceleran; Atrato, Nutibara y Urrao aceleran | C13: 3 | D13: subregiones con tasa en aumento | E13: 2017-2023 vs 2000-2008 | F13: La tasa relativa de pérdida (deforestación anual sobre bosque remanente) baja en Caribe (1,0%→0,3%) y Centro (0,5%→0,3%), pero sube en Atrato, Nutibara y Urrao. La frontera de deforestación se corre hacia las subregiones más boscosas — coherente con el desplazamiento hacia territorios étnicos.
... A15: cuencas | B15: 11.642 ha deforestadas en las cuencas monitoreadas | C15: 11642 | D15: ha (11 periodos confiables) | E15: 2000-2023 | F15: Las 7 cuencas priorizadas (723.026 ha, 38,9% de la jurisdicción) acumulan 11.642 ha de deforestación en los periodos con área confiable. El análisis detectó y excluyó un defecto de datos: en 2021-2022 la columna de área venía sin recortar contra la cuenca (2,7 M ha reportadas).

Sheet Territorios
A1: Deforestación por territorio (polígonos mapeados ≥1 ha, 2000-2024)
A3: ÁREAS PROTEGIDAS (deforestación mapeada)
A4: Área protegida | B4: Categoría | C4: Deforestación (ha)
A5: Serranía de Abibe | B5: Distrito Regional de Manejo Integrado | C5: 2165.9
A6: Carauta | B6: Reserva Forestal Protectora Nacional | C6: 528.7
A7: Ensenada de Rionegro, los Bajos Aledanos | B7: Distrito Regional de Manejo Integrado | C7: 447.4
A8: Las Orquideas | B8: Parque Nacional Natural | C8: 342.8
A9: De Urrao | B9: Reserva Forestal Protectora Nacional | C9: 121
A10: Río León | B10: Reserva Forestal Protectora Nacional | C10: 119.9
A11: Peque | B11: Distrito de Conservación de Suelos | C11: 57.7
A12: Humedales entre los Rios Leon y Suriqui | B12: Parque Regional Natural | C12: 16.9
A13: Paramillo | B13: Parque Nacional Natural | C13: 14.9
A14: Alto de Insor | B14: Distrito Regional de Manejo Integrado | C14: 10.8
A15: Los Katío | B15: Parque Nacional Natural | C15: 8.3
A16: De Las Aves Colibrí del Sol | B16: Reserva Natural de la Sociedad Civil | C16: 1
... A19: Los Horizontales | B19: Reserva Natural de la Sociedad Civil | C19: 0
A22: POMCAS — cuencas ordenadas (deforestación mapeada)
A23: POMCA | C23: Deforestación (ha)
A24: Río León | C24: 4738.5
A25: Río Turbo-Currulao | C25: 2739.2
A26: Río Sucio Alto | C26: 2368.2
A27: Río San Juan | C27: 537.2
A28: Directos al Cauca entre Río San Juan e Ituago | C28: 234.2
A29: Río Mulaticos | C29: 58.3
A30: Río Canaletes, Los Córdobas y otros arroyos | C30: 42.7
A33: RESGUARDOS INDÍGENAS (límites oficiales)
A34: Territorio | B34: Pueblo / municipios | C34: Deforestación (ha)
A35: Murindo (Rio Murindo) | B35: Embera Katío | C35: 576.6
A36: Chaquenoda | B36: Embera Katío | C36: 557.8
